<?xml version="1.0" ?>
<!-- =================================================================================== -->
<!-- |    This document was autogenerated by xacro from kr20.xacro                     | -->
<!-- |    EDITING THIS FILE BY HAND IS NOT RECOMMENDED                                 | -->
<!-- =================================================================================== -->
<robot name="kr20">
  <!-- END - Include -->
  <!-- World frame (for Gazebo) -->
  <link name="world"/>
  <!-- Arm fixed to world frame  -->
  <joint name="world__base" type="fixed">
    <parent link="world"/>
    <child link="base"/>
    <origin rpy="0 0 0" xyz="0 0 0"/>
  </joint>
  <link name="base">
    <inertial>
      <mass value="157.633"/>
      <origin rpy="0 0 0" xyz="0 0 0"/>
      <inertia ixx="13.235" ixy="0" ixz="0" iyy="13.235" iyz="0" izz="9.655"/>
    </inertial>
    <collision>
      <origin rpy="0 0 0" xyz="0 0 0"/>
      <geometry>
        <mesh filename="package://kuka_kr20_description/meshes/base_link.stl" scale="0.001 0.001 0.001"/>
      </geometry>
    </collision>
    <visual>
      <origin rpy="0 0 0" xyz="0 0 0"/>
      <geometry>
        <mesh filename="package://kuka_kr20_description/meshes/base_link.stl" scale="0.001 0.001 0.001"/>
      </geometry>
      <material name="Black"/>
    </visual>
  </link>
  <material name="Orange">
    <color rgba="0.95 0.5 0.15 1.0"/>
  </material>
  <material name="Grey">
    <color rgba="0.7 0.7 0.7 1.0"/>
  </material>
  <material name="Black">
    <color rgba="0.0 0.0 0.0 1.0"/>
  </material>
  <gazebo reference="base">
    <material>Gazebo/Black</material>
  </gazebo>
  <gazebo reference="link01">
    <material>Gazebo/Orange</material>
  </gazebo>
  <gazebo reference="link02">
    <material>Gazebo/Orange</material>
  </gazebo>
  <gazebo reference="link03">
    <material>Gazebo/Orange</material>
  </gazebo>
  <gazebo reference="link04">
    <material>Gazebo/Orange</material>
  </gazebo>
  <gazebo reference="link05">
    <material>Gazebo/Orange</material>
  </gazebo>
  <gazebo reference="link06">
    <material>Gazebo/Orange</material>
  </gazebo>
  <gazebo reference="link07">
    <material>Gazebo/Orange</material>
  </gazebo>
  <gazebo reference="linkef">
    <material>Gazebo/Orange</material>
  </gazebo>
  <!-- BEGIN - Robot description -->
  <joint name="q1" type="revolute">
    <axis xyz="0 0 1"/>
    <limit effort="1000" lower="-3.14" upper="3.14" velocity="0.5"/>
    <origin rpy="1.5708 0 3.1416" xyz="0 0 1.08725"/>
    <parent link="base"/>
    <child link="link01"/>
  </joint>
  <transmission name="trans_q1">
    <type>transmission_interface/SimpleTransmission</type>
    <joint name="q1">
      <hardwareInterface>hardware_interface/PositionJointInterface</hardwareInterface>
    </joint>
    <actuator name="motor_q1">
      <hardwareInterface>hardware_interface/PositionJointInterface</hardwareInterface>
      <mechanicalReduction>100</mechanicalReduction>
    </actuator>
  </transmission>
  <link name="link01">
    <inertial>
      <mass value="157.633"/>
      <origin rpy="0 0 0" xyz="0 0 -0.12725"/>
      <inertia ixx="13.235" ixy="0" ixz="0" iyy="13.235" iyz="0" izz="9.655"/>
    </inertial>
    <collision>
      <origin rpy="0 0 0" xyz="0 0 -0.12725"/>
      <geometry>
        <mesh filename="package://kuka_kr20_description/meshes/Link1.stl" scale="0.001 0.001 0.001"/>
      </geometry>
    </collision>
    <visual>
      <origin rpy="0 0 0" xyz="0 0 -0.12725"/>
      <geometry>
        <mesh filename="package://kuka_kr20_description/meshes/Link1.stl" scale="0.001 0.001 0.001"/>
      </geometry>
      <material name="Orange"/>
    </visual>
  </link>
  <joint name="q2" type="prismatic">
    <axis xyz="0 0 1"/>
    <limit effort="1000" lower="0.13" upper="0.5" velocity="0.5"/>
    <origin rpy="0 3.1416 0" xyz="0 -0.115 0"/>
    <parent link="link01"/>
    <child link="link02"/>
  </joint>
  <transmission name="trans_q2">
    <type>transmission_interface/SimpleTransmission</type>
    <joint name="q2">
      <hardwareInterface>hardware_interface/PositionJointInterface</hardwareInterface>
    </joint>
    <actuator name="motor_q2">
      <hardwareInterface>hardware_interface/PositionJointInterface</hardwareInterface>
      <mechanicalReduction>100</mechanicalReduction>
    </actuator>
  </transmission>
  <link name="link02">
    <inertial>
      <mass value="157.633"/>
      <origin rpy="0 0 0" xyz="0 0.11 0"/>
      <inertia ixx="13.235" ixy="0" ixz="0" iyy="13.235" iyz="0" izz="9.655"/>
    </inertial>
    <collision>
      <origin rpy="0 0 0" xyz="0 0.11 0"/>
      <geometry>
        <mesh filename="package://kuka_kr20_description/meshes/Link2.stl" scale="0.001 0.001 0.001"/>
      </geometry>
    </collision>
    <visual>
      <origin rpy="0 0 0" xyz="0 0.11 0"/>
      <geometry>
        <mesh filename="package://kuka_kr20_description/meshes/Link2.stl" scale="0.001 0.001 0.001"/>
      </geometry>
      <material name="Grey"/>
    </visual>
  </link>
  <joint name="q3" type="revolute">
    <axis xyz="0 0 1"/>
    <limit effort="1000" lower="-2.15" upper="2.15" velocity="0.5"/>
    <origin rpy="0 0 -1.5708" xyz="0 0 0.2835"/>
    <parent link="link02"/>
    <child link="link03"/>
  </joint>
  <transmission name="trans_q3">
    <type>transmission_interface/SimpleTransmission</type>
    <joint name="q3">
      <hardwareInterface>hardware_interface/PositionJointInterface</hardwareInterface>
    </joint>
    <actuator name="motor_q3">
      <hardwareInterface>hardware_interface/PositionJointInterface</hardwareInterface>
      <mechanicalReduction>100</mechanicalReduction>
    </actuator>
  </transmission>
  <link name="link03">
    <inertial>
      <mass value="157.633"/>
      <origin rpy="0 0 0" xyz="0 0 -0.08675"/>
      <inertia ixx="13.235" ixy="0" ixz="0" iyy="13.235" iyz="0" izz="9.655"/>
    </inertial>
    <collision>
      <origin rpy="0 0 0" xyz="0 0 -0.08675"/>
      <geometry>
        <mesh filename="package://kuka_kr20_description/meshes/Link3.stl" scale="0.001 0.001 0.001"/>
      </geometry>
    </collision>
    <visual>
      <origin rpy="0 0 0" xyz="0 0 -0.08675"/>
      <geometry>
        <mesh filename="package://kuka_kr20_description/meshes/Link3.stl" scale="0.001 0.001 0.001"/>
      </geometry>
      <material name="Orange"/>
    </visual>
  </link>
  <joint name="q4" type="revolute">
    <axis xyz="0 0 1"/>
    <limit effort="1000" lower="-3.14" upper="3.14" velocity="0.5"/>
    <origin rpy="0 0 -1.5708" xyz="0 -0.656 -0.13225"/>
    <parent link="link03"/>
    <child link="link04"/>
  </joint>
  <transmission name="trans_q4">
    <type>transmission_interface/SimpleTransmission</type>
    <joint name="q4">
      <hardwareInterface>hardware_interface/PositionJointInterface</hardwareInterface>
    </joint>
    <actuator name="motor_q4">
      <hardwareInterface>hardware_interface/PositionJointInterface</hardwareInterface>
      <mechanicalReduction>100</mechanicalReduction>
    </actuator>
  </transmission>
  <link name="link04">
    <inertial>
      <mass value="157.633"/>
      <origin rpy="0 0 0" xyz="0 0 -0.06425"/>
      <inertia ixx="13.235" ixy="0" ixz="0" iyy="13.235" iyz="0" izz="9.655"/>
    </inertial>
    <collision>
      <origin rpy="0 0 0" xyz="0 0 -0.06425"/>
      <geometry>
        <mesh filename="package://kuka_kr20_description/meshes/Link4.stl" scale="0.001 0.001 0.001"/>
      </geometry>
    </collision>
    <visual>
      <origin rpy="0 0 0" xyz="0 0 -0.06425"/>
      <geometry>
        <mesh filename="package://kuka_kr20_description/meshes/Link4.stl" scale="0.001 0.001 0.001"/>
      </geometry>
      <material name="Grey"/>
    </visual>
  </link>
  <joint name="q5" type="revolute">
    <axis xyz="0 0 1"/>
    <limit effort="1000" lower="-3.14" upper="3.14" velocity="0.5"/>
    <origin rpy="0 -1.5708 1.5708" xyz="0 -0.531 0.1565"/>
    <parent link="link04"/>
    <child link="link05"/>
  </joint>
  <transmission name="trans_q5">
    <type>transmission_interface/SimpleTransmission</type>
    <joint name="q5">
      <hardwareInterface>hardware_interface/PositionJointInterface</hardwareInterface>
    </joint>
    <actuator name="motor_q5">
      <hardwareInterface>hardware_interface/PositionJointInterface</hardwareInterface>
      <mechanicalReduction>100</mechanicalReduction>
    </actuator>
  </transmission>
  <link name="link05">
    <inertial>
      <mass value="157.633"/>
      <origin rpy="0 0 0" xyz="0 0 0"/>
      <inertia ixx="13.235" ixy="0" ixz="0" iyy="13.235" iyz="0" izz="9.655"/>
    </inertial>
    <collision>
      <origin rpy="0 0 0" xyz="0 0 0"/>
      <geometry>
        <mesh filename="package://kuka_kr20_description/meshes/Link5.stl" scale="0.001 0.001 0.001"/>
      </geometry>
    </collision>
    <visual>
      <origin rpy="0 0 0" xyz="0 0 0"/>
      <geometry>
        <mesh filename="package://kuka_kr20_description/meshes/Link5.stl" scale="0.001 0.001 0.001"/>
      </geometry>
      <material name="Orange"/>
    </visual>
  </link>
  <joint name="q6" type="revolute">
    <axis xyz="0 0 1"/>
    <limit effort="1000" lower="-3.14" upper="3.14" velocity="0.5"/>
    <origin rpy="1.5708 -1.5708 0" xyz="0 -0.1605 0"/>
    <parent link="link05"/>
    <child link="link06"/>
  </joint>
  <transmission name="trans_q6">
    <type>transmission_interface/SimpleTransmission</type>
    <joint name="q6">
      <hardwareInterface>hardware_interface/PositionJointInterface</hardwareInterface>
    </joint>
    <actuator name="motor_q6">
      <hardwareInterface>hardware_interface/PositionJointInterface</hardwareInterface>
      <mechanicalReduction>100</mechanicalReduction>
    </actuator>
  </transmission>
  <link name="link06">
    <inertial>
      <mass value="157.633"/>
      <origin rpy="0 0 0" xyz="0 0 -0.0605"/>
      <inertia ixx="13.235" ixy="0" ixz="0" iyy="13.235" iyz="0" izz="9.655"/>
    </inertial>
    <collision>
      <origin rpy="0 0 0" xyz="0 0 -0.0605"/>
      <geometry>
        <mesh filename="package://kuka_kr20_description/meshes/Link6.stl" scale="0.001 0.001 0.001"/>
      </geometry>
    </collision>
    <visual>
      <origin rpy="0 0 0" xyz="0 0 -0.0605"/>
      <geometry>
        <mesh filename="package://kuka_kr20_description/meshes/Link6.stl" scale="0.001 0.001 0.001"/>
      </geometry>
      <material name="Grey"/>
    </visual>
  </link>
  <joint name="q7" type="revolute">
    <axis xyz="0 0 1"/>
    <limit effort="1000" lower="-3.14" upper="3.14" velocity="0.5"/>
    <origin rpy="-1.5708 0 0" xyz="0 0 0"/>
    <parent link="link06"/>
    <child link="link07"/>
  </joint>
  <transmission name="trans_q7">
    <type>transmission_interface/SimpleTransmission</type>
    <joint name="q7">
      <hardwareInterface>hardware_interface/PositionJointInterface</hardwareInterface>
    </joint>
    <actuator name="motor_q7">
      <hardwareInterface>hardware_interface/PositionJointInterface</hardwareInterface>
      <mechanicalReduction>100</mechanicalReduction>
    </actuator>
  </transmission>
  <link name="link07">
    <inertial>
      <mass value="157.633"/>
      <origin rpy="0 0 0" xyz="0 0 0.088"/>
      <inertia ixx="13.235" ixy="0" ixz="0" iyy="13.235" iyz="0" izz="9.655"/>
    </inertial>
    <collision>
      <origin rpy="0 0 0" xyz="0 0 0.088"/>
      <geometry>
        <mesh filename="package://kuka_kr20_description/meshes/Link7.stl" scale="0.001 0.001 0.001"/>
      </geometry>
    </collision>
    <visual>
      <origin rpy="0 0 0" xyz="0 0 0.088"/>
      <geometry>
        <mesh filename="package://kuka_kr20_description/meshes/Link7.stl" scale="0.001 0.001 0.001"/>
      </geometry>
      <material name="Orange"/>
    </visual>
  </link>
  <joint name="q8" type="prismatic">
    <axis xyz="0 0 1"/>
    <limit effort="1000" lower="-0.08" upper="0.08" velocity="0.5"/>
    <origin rpy="0 -1.5708 0" xyz="0 0 0"/>
    <parent link="link07"/>
    <child link="linkef"/>
  </joint>
  <transmission name="trans_q8">
    <type>transmission_interface/SimpleTransmission</type>
    <joint name="q8">
      <hardwareInterface>hardware_interface/PositionJointInterface</hardwareInterface>
    </joint>
    <actuator name="motor_q8">
      <hardwareInterface>hardware_interface/PositionJointInterface</hardwareInterface>
      <mechanicalReduction>100</mechanicalReduction>
    </actuator>
  </transmission>
  <link name="linkef">
    <inertial>
      <mass value="157.633"/>
      <origin rpy="0 0 0" xyz="0 0 -0.15"/>
      <inertia ixx="13.235" ixy="0" ixz="0" iyy="13.235" iyz="0" izz="9.655"/>
    </inertial>
    <collision>
      <origin rpy="0 0 0" xyz="0 0 -0.15"/>
      <geometry>
        <mesh filename="package://kuka_kr20_description/meshes/Link_EF.stl" scale="0.001 0.001 0.001"/>
      </geometry>
    </collision>
    <visual>
      <origin rpy="0 0 0" xyz="0 0 -0.15"/>
      <geometry>
        <mesh filename="package://kuka_kr20_description/meshes/Link_EF.stl" scale="0.001 0.001 0.001"/>
      </geometry>
      <material name="Black"/>
    </visual>
  </link>
</robot>

